<?xml version="1.0"?>
<robot name="plate">
	<link name="base_link">
		<visual>
			<geometry>
				<cylinder length="2" radius="0.01"/>
			</geometry>
			<material name="blue">
				<color rgba="0 0 .8 1"/>
			</material>
			<origin rpy="0 0 0" xyz="0 0 .125"/>
		</visual>
<!-- 		<collision>
			<geometry>
				<cylinder length="6" radius="0.01"/>
			</geometry>
			<origin rpy="0 0 0" xyz="0 0 .125"/>
		</collision> -->
		<inertial>
			<mass value="0"/> 	<!-- fixed-->
			<inertia ixx="1.0" ixy="0.0" ixz="0.0" iyy="1.0" iyz="0.0" izz="1.0"/>
			<!-- <origin rpy="0 0 0" xyz="0 0 .125"/> -->
		</inertial>
  	</link>

  	<link name="small_link">
<!-- 		<visual>
			<geometry>
				<cylinder length="0.00001" radius="0.00001"/>
			</geometry>
			<origin rpy="0 0 0" xyz="0 0 0"/>
			<material name="white">
				<color rgba="1 1 1 1"/>
			</material>
		</visual> -->
<!-- 		<collision>
			<geometry>
				<cylinder length="0.00001" radius="0.00001"/>
			</geometry>
			<origin rpy="0 0 0" xyz="0 0 0"/>
		</collision> -->
		<inertial>
			<mass value="0"/>
			<origin rpy="0 0 0" xyz="0 0 0"/>
			<inertia ixx="1.0" ixy="0.0" ixz="0.0" iyy="1.0" iyz="0.0" izz="1.0"/>
		</inertial>
  	</link>

	<joint name="base_to_small" type="continuous">
		<parent link="base_link"/>
		<child link="small_link"/>
		<origin xyz="0 0 .25"/>
		<axis xyz="1 0 0" />
	</joint>

	<link name="plate_link">
		<visual>
			<geometry>
				<!-- <box size="1. 1 0.01"/> -->
				<box size="1 1 0.01"/>
			</geometry>
			<origin rpy="0 0 0.5" xyz="0 0 0.5"/>
			<material name="white">
				<color rgba="1 1 1 1"/>
			</material>
		</visual>
		<collision>
			<geometry>
				<box size="1 1 0.01"/>
			</geometry>
			<origin rpy="0 0 0.5" xyz="0 0 0.5"/>
		</collision>
		<inertial>
			<mass value="0.415"/>
			<origin rpy="0 0 0" xyz="0 0 0"/>
			<inertia ixx="1.0" ixy="0.0" ixz="0.0" iyy="1.0" iyz="0.0" izz="1.0"/>
		</inertial>
	</link>

	<joint name="small_to_plate" type="continuous">
		<parent link="small_link"/>
		<child link="plate_link"/>
		<origin xyz="0 0 0"/>
		<axis xyz="0 1 0" />
	</joint>

</robot>